Workbook
Name 工事長名: OFFSET(#REF!,1,0,MATCH("-",#REF!,0)-2,1)

Sheet 交通費(宿泊無)
A1: 来社日 | B1: 46237 | D1: ～ | E1: 46241 | K1: 【Yahoo! 乗換案内】
A2: 氏名 | B2: 卜部颯斗 | K2: https://transit.yahoo.co.jp/
A3: 振込金額 | B3: =SUM(K13:K25) -> 10450
A5: 【申請ルール】
A6: ※定期区間外のみ 申請してください。
A7: 移動手段 | C7: 具体例 | G7: 添付書類
A8: 電車・バス | C8: 電車・バス | G8: Yahoo!経路案内のスクリーンショット
A9: 電車・バス以外 | C9: 新幹線･特急･飛行機・船舶・夜行バス | G9: 領収書
A11: 【行き（自宅最寄り ⇒ 会社）】
A12: No | B12: 移動手段 | C12: 区間（駅・停留所・空港名） | F12: 片道金額 | I12: 回数 | K12: 総額 | M12: 備考
A13: =IF(B13="","",COUNTIF($B$13:B13,"<>")) -> 1 | B13: 電車・バス | C13: 南林間 | D13: ⇒ | E13: 三田 | F13: 1045 | G13: 円 | H13: × | I13: 5 | J13: 回 | K13: =IF(D13=マスタ!$A$3,F13*2,F13)*I13 -> 5225 | L13: 円
A14: =IF(B14="","",COUNTIF($B$13:B14,"<>")) | D14: ⇒ | G14: 円 | H14: × | J14: 回 | K14: =IF(D14=マスタ!$A$3,F14*2,F14)*I14 -> 0 | L14: 円
A15: =IF(B15="","",COUNTIF($B$13:B15,"<>")) | D15: ⇒ | G15: 円 | H15: × | J15: 回 | K15: =IF(D15=マスタ!$A$3,F15*2,F15)*I15 -> 0 | L15: 円
A16: =IF(B16="","",COUNTIF($B$13:B16,"<>")) | D16: ⇒ | G16: 円 | H16: × | J16: 回 | K16: =IF(D16=マスタ!$A$3,F16*2,F16)*I16 -> 0 | L16: 円
A17: =IF(B17="","",COUNTIF($B$13:B17,"<>")) | D17: ⇒ | G17: 円 | H17: × | J17: 回 | K17: =IF(D17=マスタ!$A$3,F17*2,F17)*I17 -> 0 | L17: 円
A19: 【帰り（会社 ⇒ 自宅最寄り）】
A20: No | B20: 移動手段 | C20: 区間（駅・停留所・空港名） | F20: 片道金額 | I20: 回数 | K20: 総額 | M20: 備考
A21: =IF(B21="","",COUNTIF($B$13:B21,"<>")-1) -> 2 | B21: 電車・バス | C21: 三田 | D21: ⇒ | E21: 南林間 | F21: 1045 | G21: 円 | H21: × | I21: 5 | J21: 回 | K21: =IF(D21=マスタ!$A$3,F21*2,F21)*I21 -> 5225 | L21: 円
A22: =IF(B22="","",COUNTIF($B$13:B22,"<>")-1) | D22: ⇒ | G22: 円 | H22: × | J22: 回 | K22: =IF(D22=マスタ!$A$3,F22*2,F22)*I22 -> 0 | L22: 円
A23: =IF(B23="","",COUNTIF($B$13:B23,"<>")-1) | D23: ⇒ | G23: 円 | H23: × | J23: 回 | K23: =IF(D23=マスタ!$A$3,F23*2,F23)*I23 -> 0 | L23: 円
A24: =IF(B24="","",COUNTIF($B$13:B24,"<>")-1) | D24: ⇒ | G24: 円 | H24: × | J24: 回 | K24: =IF(D24=マスタ!$A$3,F24*2,F24)*I24 -> 0 | L24: 円
A25: =IF(B25="","",COUNTIF($B$13:B25,"<>")-1) | D25: ⇒ | G25: 円 | H25: × | J25: 回 | K25: =IF(D25=マスタ!$A$3,F25*2,F25)*I25 -> 0 | L25: 円
A27: 【証明書添付】
A28: 1 | G28: 2
A29: 添付書類 | B29: =IF(B13=マスタ!$B$2,マスタ!$C$2,IF(B13=マスタ!$B$3,マスタ!$C$3,"")) -> Yahoo!乗換案内のスクリーンショット | G29: =IF(I29="","",$A$29) -> 添付書類 | I29: =IF(O29=マスタ!$B$2,マスタ!$C$2,IF(O29=マスタ!$B$3,マスタ!$C$3,"")) -> Yahoo!乗換案内のスクリーンショット | O29: =IFERROR(INDEX($B$13:$B$25,MATCH(G28,$A$13:$A$25,0)),"2空白") -> 電車・バス
A30: 確認事項 | B30: =IF(B13=マスタ!$B$2,マスタ!$D$2,IF(B13=マスタ!$B$3,マスタ!$D$3,"")) -> ● 区間・金額が申請と一致している ● 在来線（電車・バス）のみ → 乗換があっても1行で申請 ● 在来線以外も利用 → その前後で区間を分けて申請 | G30: =IF(I30="","",$A$30) -> 確認事項 | I30: =IF(O29=マスタ!$B$2,マスタ!$D$2,IF(O29=マスタ!$B$3,マスタ!$D$3,"")) -> ● 区間・金額が申請と一致している ● 在来線（電車・バス）のみ → 乗換があっても1行で申請 ● 在来線以外も利用 → その前後で区間を分けて申請
A31: =IF(B13=マスタ!$B$2,マスタ!$E$2,IF(B13=マスタ!$B$3,マスタ!$E$3,"")) -> この枠いっぱいに画像を貼付 ※行き帰り同じ経路・金額の場合、帰りは画像空欄でOK | G31: =IF(O29=マスタ!$B$2,マスタ!$E$2,IF(O29=マスタ!$B$3,マスタ!$E$3,"")) -> この枠いっぱいに画像を貼付 ※行き帰り同じ経路・金額の場合、帰りは画像空欄でOK
A32: 3 | G32: 4
A33: =IF(B33="","",$A$29) | B33: =IF(O33=マスタ!$B$2,マスタ!$C$2,IF(O33=マスタ!$B$3,マスタ!$C$3,"")) | G33: =IF(I33="","",$A$29) | I33: =IF(O34=マスタ!$B$2,マスタ!$C$2,IF(O34=マスタ!$B$3,マスタ!$C$3,"")) | O33: =IFERROR(INDEX($B$13:$B$25,MATCH(A32,$A$13:$A$25,0)),"3空白") -> 3空白
A34: =IF(B34="","",$A$30) | B34: =IF(O33=マスタ!$B$2,マスタ!$D$2,IF(O33=マスタ!$B$3,マスタ!$D$3,"")) | G34: =IF(I34="","",$A$30) | I34: =IF(O34=マスタ!$B$2,マスタ!$D$2,IF(O34=マスタ!$B$3,マスタ!$D$3,"")) | O34: =IFERROR(INDEX($B$13:$B$25,MATCH(G32,$A$13:$A$25,0)),"4空白") -> 4空白
A35: =IF(O33=マスタ!$B$2,マスタ!$E$2,IF(O33=マスタ!$B$3,マスタ!$E$3,"")) | G35: =IF(O34=マスタ!$B$2,マスタ!$E$2,IF(O34=マスタ!$B$3,マスタ!$E$3,""))
A36: 5 | G36: 6
A37: =IF(B37="","",$A$29) | B37: =IF(O37=マスタ!$B$2,マスタ!$C$2,IF(O37=マスタ!$B$3,マスタ!$C$3,"")) | G37: =IF(I37="","",$A$29) | I37: =IF(O38=マスタ!$B$2,マスタ!$C$2,IF(O38=マスタ!$B$3,マスタ!$C$3,"")) | O37: =IFERROR(INDEX($B$13:$B$25,MATCH(A36,$A$13:$A$25,0)),"5空白") -> 5空白
A38: =IF(B38="","",$A$30) | B38: =IF(O37=マスタ!$B$2,マスタ!$D$2,IF(O37=マスタ!$B$3,マスタ!$D$3,"")) | G38: =IF(I38="","",$A$30) | I38: =IF(O38=マスタ!$B$2,マスタ!$D$2,IF(O38=マスタ!$B$3,マスタ!$D$3,"")) | O38: =IFERROR(INDEX($B$13:$B$25,MATCH(G36,$A$13:$A$25,0)),"6空白") -> 6空白
A39: =IF(O37=マスタ!$B$2,マスタ!$E$2,IF(O37=マスタ!$B$3,マスタ!$E$3,"")) | G39: =IF(O38=マスタ!$B$2,マスタ!$E$2,IF(O38=マスタ!$B$3,マスタ!$E$3,""))
A40: 7 | G40: 8
A41: =IF(B41="","",$A$29) | B41: =IF(O41=マスタ!$B$2,マスタ!$C$2,IF(O41=マスタ!$B$3,マスタ!$C$3,"")) | G41: =IF(I41="","",$A$29) | I41: =IF(O42=マスタ!$B$2,マスタ!$C$2,IF(O42=マスタ!$B$3,マスタ!$C$3,"")) | O41: =IFERROR(INDEX($B$13:$B$25,MATCH(A40,$A$13:$A$25,0)),"7空白") -> 7空白
A42: =IF(B42="","",$A$30) | B42: =IF(O41=マスタ!$B$2,マスタ!$D$2,IF(O41=マスタ!$B$3,マスタ!$D$3,"")) | G42: =IF(I42="","",$A$30) | I42: =IF(O42=マスタ!$B$2,マスタ!$D$2,IF(O42=マスタ!$B$3,マスタ!$D$3,"")) | O42: =IFERROR(INDEX($B$13:$B$25,MATCH(G40,$A$13:$A$25,0)),"8空白") -> 8空白
A43: =IF(O41=マスタ!$B$2,マスタ!$E$2,IF(O41=マスタ!$B$3,マスタ!$E$3,"")) | G43: =IF(O42=マスタ!$B$2,マスタ!$E$2,IF(O42=マスタ!$B$3,マスタ!$E$3,""))
A44: 9 | G44: 10
...

Sheet 交通費(宿泊有)
A1: 来社日 | D1: ～ | K1: 【Yahoo! 乗換案内】
A2: 氏名 | K2: https://transit.yahoo.co.jp/
A3: 振込金額 | B3: =SUM(K13:K30) -> 0
A5: 【申請ルール】
A6: ※定期区間外のみ 申請してください。
A7: 移動手段 | C7: 具体例 | G7: 添付書類
A8: 電車・バス | C8: 電車・バス | G8: Yahoo!経路案内のスクリーンショット
A9: 電車・バス以外 | C9: 新幹線･特急･飛行機・船舶・夜行バス | G9: 領収書
A11: 【前日（自宅最寄り ⇒ ホテル）】
A12: No | B12: 移動手段 | C12: 区間（駅・停留所・空港名） | F12: 片道金額 | I12: 回数 | K12: 総額 | M12: 備考
A13: =IF(B13="","",COUNTIF($B$13:B13,"<>")) | D13: ⇒ | G13: 円 | H13: × | I13: 1 | J13: 回 | K13: =F13*I13 -> 0 | L13: 円
A14: =IF(B14="","",COUNTIF($B$13:B14,"<>")) | D14: ⇒ | G14: 円 | H14: × | I14: 1 | J14: 回 | K14: =F14*I14 -> 0 | L14: 円
A15: =IF(B15="","",COUNTIF($B$13:B15,"<>")) | D15: ⇒ | G15: 円 | H15: × | I15: 1 | J15: 回 | K15: =F15*I15 -> 0 | L15: 円
A16: =IF(B16="","",COUNTIF($B$13:B16,"<>")) | D16: ⇒ | G16: 円 | H16: × | I16: 1 | J16: 回 | K16: =F16*I16 -> 0 | L16: 円
A17: =IF(B17="","",COUNTIF($B$13:B17,"<>")) | D17: ⇒ | G17: 円 | H17: × | I17: 1 | J17: 回 | K17: =F17*I17 -> 0 | L17: 円
A19: 【初日・中日（会社 ⇔ ホテル）】
A20: No | B20: 移動手段 | C20: 区間（駅・停留所・空港名） | F20: 片道金額 | I20: 回数 | K20: 総額 | M20: 備考
A21: =IF(B21="","",COUNTIF($B$13:B21,"<>")-1) | D21: ⇔ | G21: 円 | H21: × | J21: 回 | K21: =IF(D21=マスタ!$A$3,F21*2,F21)*I21 -> 0 | L21: 円
A22: =IF(B22="","",COUNTIF($B$13:B22,"<>")-1) | D22: ⇔ | G22: 円 | H22: × | J22: 回 | K22: =IF(D22=マスタ!$A$3,F22*2,F22)*I22 -> 0 | L22: 円
A24: 【最終日（ホテル・会社 ⇒ 自宅最寄り）】
A25: No | B25: 移動手段 | C25: 区間（駅・停留所・空港名） | F25: 片道金額 | I25: 回数 | K25: 総額 | M25: 備考
A26: =IF(B26="","",COUNTIF($B$13:B26,"<>")-2) | D26: ⇒ | G26: 円 | H26: × | I26: 1 | J26: 回 | K26: =IF(D26=マスタ!$A$3,F26*2,F26)*I26 -> 0 | L26: 円
A27: =IF(B27="","",COUNTIF($B$13:B27,"<>")-2) | D27: ⇒ | G27: 円 | H27: × | I27: 1 | J27: 回 | K27: =IF(D27=マスタ!$A$3,F27*2,F27)*I27 -> 0 | L27: 円
A28: =IF(B28="","",COUNTIF($B$13:B28,"<>")-2) | D28: ⇒ | G28: 円 | H28: × | I28: 1 | J28: 回 | K28: =IF(D28=マスタ!$A$3,F28*2,F28)*I28 -> 0 | L28: 円
A29: =IF(B29="","",COUNTIF($B$13:B29,"<>")-2) | D29: ⇒ | G29: 円 | H29: × | I29: 1 | J29: 回 | K29: =IF(D29=マスタ!$A$3,F29*2,F29)*I29 -> 0 | L29: 円
A30: =IF(B30="","",COUNTIF($B$13:B30,"<>")-2) | D30: ⇒ | G30: 円 | H30: × | I30: 1 | J30: 回 | K30: =IF(D30=マスタ!$A$3,F30*2,F30)*I30 -> 0 | L30: 円
A32: 【証明書添付】
A33: 1 | G33: 2
A34: 添付書類 | B34: =IF(B13=マスタ!$B$2,マスタ!$C$2,IF(B13=マスタ!$B$3,マスタ!$C$3,"")) | G34: =IF(I34="","",$A$34) | I34: =IF(O34=マスタ!$B$2,マスタ!$C$2,IF(O34=マスタ!$B$3,マスタ!$C$3,"")) | O34: =IFERROR(INDEX($B$13:$B$30,MATCH(G33,$A$13:$A$30,0)),"2空白") -> 2空白
A35: 確認事項 | B35: =IF(B13=マスタ!$B$2,マスタ!$D$2,IF(B13=マスタ!$B$3,マスタ!$D$3,"")) | G35: =IF(I35="","",$A$35) | I35: =IF(O34=マスタ!$B$2,マスタ!$D$2,IF(O34=マスタ!$B$3,マスタ!$D$3,""))
A36: =IF(B13=マスタ!$B$2,マスタ!$E$2,IF(B13=マスタ!$B$3,マスタ!$E$3,"")) | G36: =IF(O34=マスタ!$B$2,マスタ!$E$2,IF(O34=マスタ!$B$3,マスタ!$E$3,""))
A37: 3 | G37: 4
A38: =IF(B38="","",$A$34) | B38: =IF(O38=マスタ!$B$2,マスタ!$C$2,IF(O38=マスタ!$B$3,マスタ!$C$3,"")) | G38: =IF(I38="","",$A$34) | I38: =IF(O39=マスタ!$B$2,マスタ!$C$2,IF(O39=マスタ!$B$3,マスタ!$C$3,"")) | O38: =IFERROR(INDEX($B$13:$B$30,MATCH(A37,$A$13:$A$30,0)),"3空白") -> 3空白
A39: =IF(B39="","",$A$35) | B39: =IF(O38=マスタ!$B$2,マスタ!$D$2,IF(O38=マスタ!$B$3,マスタ!$D$3,"")) | G39: =IF(I39="","",$A$35) | I39: =IF(O39=マスタ!$B$2,マスタ!$D$2,IF(O39=マスタ!$B$3,マスタ!$D$3,"")) | O39: =IFERROR(INDEX($B$13:$B$30,MATCH(G37,$A$13:$A$30,0)),"4空白") -> 4空白
A40: =IF(O38=マスタ!$B$2,マスタ!$E$2,IF(O38=マスタ!$B$3,マスタ!$E$3,"")) | G40: =IF(O39=マスタ!$B$2,マスタ!$E$2,IF(O39=マスタ!$B$3,マスタ!$E$3,"")) | N40: ]
A41: 5 | G41: 6
A42: =IF(B42="","",$A$34) | B42: =IF(O42=マスタ!$B$2,マスタ!$C$2,IF(O42=マスタ!$B$3,マスタ!$C$3,"")) | G42: =IF(I42="","",$A$34) | I42: =IF(O43=マスタ!$B$2,マスタ!$C$2,IF(O43=マスタ!$B$3,マスタ!$C$3,"")) | O42: =IFERROR(INDEX($B$13:$B$30,MATCH(A41,$A$13:$A$30,0)),"5空白") -> 5空白
A43: =IF(B43="","",$A$35) | B43: =IF(O42=マスタ!$B$2,マスタ!$D$2,IF(O42=マスタ!$B$3,マスタ!$D$3,"")) | G43: =IF(I43="","",$A$35) | I43: =IF(O43=マスタ!$B$2,マスタ!$D$2,IF(O43=マスタ!$B$3,マスタ!$D$3,"")) | O43: =IFERROR(INDEX($B$13:$B$30,MATCH(G41,$A$13:$A$30,0)),"6空白") -> 6空白
A44: =IF(O42=マスタ!$B$2,マスタ!$E$2,IF(O42=マスタ!$B$3,マスタ!$E$3,"")) | G44: =IF(O43=マスタ!$B$2,マスタ!$E$2,IF(O43=マスタ!$B$3,マスタ!$E$3,""))
A45: 7 | G45: 8
...

Sheet 口座情報
A2: ◆振込口座情報
A3: 青色のセル を入力してください。
C4: 氏名 | E4: 銀行コード | G4: 銀行名 | I4: 支店コード | K4: 支店名 | M4: 口座番号 | O4: 口座名義(ｶﾅ) | Q4: 振込金額
A5: 記載例１ | C5: 山田太郎 | E5: 0001 | G5: みずほ | I5: 130 | K5: 新橋 | M5: 9999999 | O5: ﾔﾏﾀﾞ ﾀﾛｳ | Q5: 5000
A6: 記載例２ | C6: 山田花子 | E6: 9900 | G6: ゆうちょ | I6: 198 | K6: 一九八 | M6: 123456 | O6: ﾔﾏﾀﾞ ﾊﾅｺ | Q6: 5000
A7: 1 | B7: , | C7: 卜部颯斗 | D7: , | E7: 0009 | F7: , | G7: 三井住友 | H7: , | I7: 693 | J7: , | K7: 巣鴨 | L7: , | M7: 7677654 | N7: , | O7: ｳﾗﾍﾞ ｶｲﾄ | P7: , | Q7: 10450
A10: ◆画像添付 | H10: 5
A11: 銀行名・支店名・口座番号・口座名義 が分かる写真を添付してください。
A12: 例：通帳、ネットバンキングのスクリーンショット
A13: サンプル | I13: 画像貼付欄
I14: ※この枠いっぱいに画像を貼付

Sheet マスタ
A1: 矢印 | B1: 移動手段 | C1: 添付物 | D1: 確認事項のみ | E1: 画像添付欄 | F1: 申請種別 | G1: 添付物 | H1: 確認事項
A2: ⇒ | B2: 電車・バス | C2: Yahoo!乗換案内のスクリーンショット | D2: ● 区間・金額が申請と一致している ● 在来線（電車・バス）のみ → 乗換があっても1行で申請 ● 在来線以外も利用 → その前後で区間を分けて申請 | E2: この枠いっぱいに画像を貼付 ※行き帰り同じ経路・金額の場合、帰りは画像空欄でOK | F2: 高速道路 | G2: ETCカード明細 or 領収書 | H2: ● 区間・金額が申請と一致している ● 途中で料金所を挟んでも1行で申請
A3: ⇔ | B3: 電車・バス以外 | C3: 領収書 | D3: ● 宛名が社名になっている ● 区間・金額が申請と一致している | E3: この枠いっぱいに画像を貼付 ※行き帰りともに領収書貼付必須 | F3: 駐車場 | G3: コインパーキングの領収書 | H3: ● 区間・金額が申請と一致している
F4: ガソリン | G4: Google Mapのスクリーンショット | H4: ● 距離の表記が申請と一致している ● 車での経路で最短の走行距離になっている

Sheet 現金廃止
A1: 学生交通費支払フロー 現金対応と振込対応の比較
A3: ◆現金対応 | F3: ◆振込対応
A4: No | B4: 担当 | C4: To Do | D4: 分数 | F4: No | G4: 担当 | H4: To Do | I4: 分数
A5: 1 | B5: 人開 | C5: 学生からの申請内容確認・やり取り（AOL） | D5: 2 | F5: 1 | G5: 人開 | H5: Forms回答の確認 | I5: 2
A6: 2 | B6: 人開 | C6: Excel作成 | D6: 5 | F6: 2 | G6: 人開 | H6: Excel作成 | I6: 5
A7: 3 | B7: 人開 | C7: 出金申請書作成 | D7: 2 | F7: 3 | G7: 人開 | H7: 振込口座申請書作成 | I7: 2
A8: 4 | B8: 人開 | C8: かんたん申請 | D8: 5 | F8: 4 | G8: 人開 | H8: かんたん申請 | I8: 5 | K8: 現金対応時間-振込対応時間
A9: 5 | B9: 人開 | C9: Teamsチャット | D9: 2 | F9: 5 | G9: 経理 | H9: かんたん申請確認 | I9: 1 | K9: =D26-I26 -> 36
A10: 6 | B10: 経理 | C10: かんたん申請確認 | D10: 1 | F10: 6 | G10: 経理 | H10: 申請書類内容確認 | I10: 3
A11: 7 | B11: 経理 | C11: 申請書類内容確認 | D11: 3 | F11: 7 | G11: 経理 | H11: 申請書・振込口座申請書DL、PDF格納、ファイル名変更 | I11: 2 | M11: 分
A12: 8 | B12: 経理 | C12: 申請書・出金申請書印刷、押印 | D12: 5 | F12: 8 | G12: 経理 | H12: CMS取込用テキストファイル作成 | I12: 3 | M12: ※注1 | O12: ※1件あたり
A13: 9 | B13: 経理 | C13: 金庫を開け現金出金、封筒へ | D13: 5 | F13: 9 | G13: 経理 | H13: CMSにテキストファイル取込、支払いデータ明細一覧（作成中）出力、フォルダ格納 | I13: 3 | K13: 時間差 (分) | M13: 分給 (円) | O13: 削減できるコスト (円)
A14: 10 | B14: 経理 | C14: 印刷した申請書類と現金封筒をクリアファイルに入れる | D14: 1 | F14: 10 | G14: 経理 | H14: 振込口座申請書と支払いデータ明細一覧（作成中）の情報照合、押印 | I14: 2 | K14: =K9 -> 36 | L14: × | M14: =G32 -> 28.888889 | N14: = | O14: =K14*M14 -> 1040
A15: 11 | B15: 経理 | C15: 経理内承認 | D15: 10 | F15: 11 | G15: 経理 | H15: 経理内でTeamsチャットで承認依頼 | I15: 1
A16: 12 | B16: 経理 | C16: 人開へ申請書類と現金封筒のファイルを手渡し | D16: 5 | F16: 12 | G16: 経理 | H16: 経理内承認 | I16: 10 | K16: ※1件あたりの振込手数料は 220 円
A17: 13 | B17: 人開 | C17: 出金申請書の受領印にサイン、学生へ現金手渡し、受領サイン求 | D17: 3 | F17: 13 | G17: 経理 | H17: 支払いデータ明細一覧（承認済）出力、フォルダへ保存 | I17: 1 | K17: （30,000円以上の支払は振込対応のため、現金対応なし）
A18: 14 | B18: 人開 | C18: 経理へ受領サイン済のファイルを手渡し | D18: 5 | F18: 14 | G18: 経理 | H18: 支払いデータ明細一覧（作成中）と（承認）の情報照合、押印 | I18: 2
A19: 15 | B19: 経理 | C19: 金庫内すべての現金を数え、現金照合表作成 | D19: 10 | F19: 15 | G19: 経理 | H19: 経理内Teamsチャット | I19: 1
A20: 16 | B20: 経理 | C20: 金庫内すべての現金を数え、現金照合表確認（承認者） | D20: 5 | F20: 16 | G20: 経理 | H20: 経理内承認 | I20: 10
A21: 17 | B21: 経理 | C21: 経理内承認 | D21: 10 | F21: 17 | G21: 経理 | H21: かんたん申請承認、人開へTeamsチャットで振込日連絡 | I21: 1 | K21: 全件振込対応にすることで、
A22: 18 | B22: 経理 | C22: かんたん申請承認 | D22: 1 | F22: 18 | G22: 経理 | H22: PDFをTOKIUMへアップロード | I22: 3 | K22: =O14-220 -> 820
A23: 19 | B23: 経理 | C23: 承認済申請書類をファイリング | D23: 5 | L23: 円 | M23: のコスト削減が可能。
A24: 20 | B24: 経理 | C24: 承認済申請書類をスキャンしてPDF格納 | D24: 5
A25: 21 | B25: 経理 | C25: PDFをTOKIUMへアップロード | D25: 3
A26: 合計（分） | D26: =SUM(D5:D25) -> 93 | F26: 合計（分） | I26: =SUM(I5:I24) -> 57
A28: ◆現金対応の課題 | F28: ※注1：分給の根拠
A29: ・来社日当日に出金、経理内承認が必要、事前準備不可（朝一出金だとスケジュール次第でバタつく） | F29: 月給 | G29: 260000 | H29: ←新卒の給与で計算しています
A30: ・チャット漏れ、かんたん申請確認漏れの可能性があり、その場合、学生が帰るまでに急ぎ現金を準備する必要がある | F30: 日給 | G30: =G29/20 -> 13000
A31: ➡経理不在の可能性あり | F31: 時給 | G31: =G30/7.5 -> 1733.3333
A32: ・現金を数え、照合表を作成することが振込対応と比べ時間がかかる | F32: 分給 | G32: =G31/60 -> 28.888889
A33: ・出金申請書が振込口座申請書の作成と比べ、時間がかかる
A34: ・申請書を印刷し学生に紙にサインさせている
A35: ➡ペーパーレス化

Sheet 現金廃止２
A1: ◆学生交通費の振込件数・出金申請件数
A2: （2025年）
A3: 月 | B3: 振込 | D3: 出金申請 | F3: 合計
B4: 件数 | C4: 金額 | D4: 件数 | E4: 金額 | F4: 件数 | G4: 金額
A5: 1月 | B5: 11 | C5: 121292 | D5: 11 | E5: 13095 | F5: 22 | G5: 134387
A6: 2月 | B6: 1 | C6: 1564 | D6: 3 | E6: 2908 | F6: 4 | G6: 4472
A7: 3月 | B7: 1 | C7: 29345 | D7: 1 | E7: 684 | F7: 2 | G7: 30029
A8: 4月 | B8: 4 | C8: 2854 | D8: 7 | E8: 8902 | F8: 11 | G8: 11756
A9: 5月 | B9: 5 | C9: 5599 | D9: 8 | E9: 7229 | F9: 13 | G9: 12828
A10: 6月 | B10: 6 | C10: 24649 | D10: 8 | E10: 31275 | F10: 14 | G10: 55924
A11: 7月 | B11: 2 | C11: 22429 | D11: 9 | E11: 31306 | F11: 11 | G11: 53735
A12: 8月 | B12: 43 | C12: 451074 | D12: 3 | E12: 23099 | F12: 46 | G12: 474173
A13: 9月 | B13: 112 | C13: 1359024 | D13: 0 | E13: 0 | F13: 112 | G13: 1359024
A14: 10月 | B14: 99 | C14: 1276961 | D14: 0 | E14: 0 | F14: 99 | G14: 1276961
A15: 11月 | B15: 0 | C15: 0 | D15: 0 | E15: 0 | F15: 0 | G15: 0
A16: 12月 | B16: 0 | C16: 0 | D16: 0 | E16: 0 | F16: 0 | G16: 0
A17: 合計 | B17: 284 | C17: 3294791 | D17: 50 | E17: 118498 | F17: 334 | G17: 3413289
D19: =現金廃止!K22*現金廃止２!D17 -> 41000 | E19: 円の削減

Sheet ×交通費(日付あり)
A1: 氏名 | B1: 山田太郎 | H1: 路線検索はこちらをご利用ください↓↓
A2: 振込金額 | B2: =SUM(G12:G36) -> 14640 | H2: https://transit.yahoo.co.jp/
A4: 【申請ルール】
A5: ※定期区間外のみ 申請してください。
A6: 移動手段 | B6: 具体例 | F6: 往復同額の場合 | H6: 往復異なる場合 | I6: 添付書類
A7: 在来線 | B7: 電車・バス | F7: 1行でOK（⇔） | H7: 行を分ける（⇒） | I7: Yahoo!経路案内のスクリーンショット
A8: 在来線以外 | B8: 新幹線･特急･飛行機・船舶・夜行バス | F8: 必ず行を分ける（⇔ は使わない） | I8: 領収書
A11: 利用日付 | B11: 移動手段 | C11: 区間（駅・空港名） | F11: 片道金額 | G11: 総額 | H11: 証拠書添付 | J11: 備考
A12: 46114 | B12: 在来線 | C12: 大阪 | D12: ⇔ | E12: 新大阪 | F12: 240 | G12: =IF(IF(D12=マスタ!$A$3,F12*2,F12)*COUNTA(A12:A16)=0,"",IF(D12=マスタ!$A$3,F12*2,F12)*COUNTA(A12:A16)) -> 960 | H12: =IF(B12=マスタ!$B$2,マスタ!#REF!,IF(B12=マスタ!$B$3,マスタ!#REF!,""))
A13: 46117
B17: 在来線以外 | C17: 新大阪 | D17: ⇒ | E17: 品川 | F17: 13370 | G17: =IF(IF(D17=マスタ!$A$3,F17*2,F17)*COUNTA(A17:A21)=0,"",IF(D17=マスタ!$A$3,F17*2,F17)*COUNTA(A17:A21)) -> 13370 | H17: =IF(B17=マスタ!$B$2,マスタ!#REF!,IF(B17=マスタ!$B$3,マスタ!#REF!,""))
A19: 46114
B22: 在来線 | C22: 品川 | D22: ⇔ | E22: 田町 | F22: 155 | G22: =IF(IF(D22=マスタ!$A$3,F22*2,F22)*COUNTA(A22:A26)=0,"",IF(D22=マスタ!$A$3,F22*2,F22)*COUNTA(A22:A26)) -> 310 | H22: =IF(B22=マスタ!$B$2,マスタ!#REF!,IF(B22=マスタ!$B$3,マスタ!#REF!,""))
A24: 46114
G27: =IF(IF(D27=マスタ!$A$3,F27*2,F27)*COUNTA(A27:A31)=0,"",IF(D27=マスタ!$A$3,F27*2,F27)*COUNTA(A27:A31)) | H27: =IF(B27=マスタ!$B$2,マスタ!#REF!,IF(B27=マスタ!$B$3,マスタ!#REF!,""))
G32: =IF(IF(D32=マスタ!$A$3,F32*2,F32)*COUNTA(A32:A36)=0,"",IF(D32=マスタ!$A$3,F32*2,F32)*COUNTA(A32:A36)) | H32: =IF(B32=マスタ!$B$2,マスタ!#REF!,IF(B32=マスタ!$B$3,マスタ!#REF!,""))
